2021-12-29 16:56:12,418 ERROR rest_utils.py:build_response:61  Response: 400 Failed {'contact': [ErrorDetail(string='Ensure this field has at least 5 characters.', code='min_length')]} None
2021-12-29 16:56:12,418 DEBUG rest_utils.py:build_response:78  Response: 200 OK 400 Failed {'contact': [ErrorDetail(string='Ensure this field has at least 5 characters.', code='min_length')]} None
2021-12-29 17:40:58,284 DEBUG rest_utils.py:build_response:78  Response: 200 OK 200 User Successfully Login None None
2021-12-29 17:43:34,380 DEBUG rest_utils.py:build_response:78  Response: 200 OK 200 User Successfully Login None None
2021-12-29 17:55:47,973 DEBUG rest_utils.py:build_response:78  Response: 200 OK 200 User Successfully Login None None
2021-12-29 18:09:43,325 DEBUG rest_utils.py:build_response:78  Response: 200 OK 200 User Successfully Login None None
2021-12-29 18:29:37,577 ERROR rest_utils.py:build_response:61  Response: 500 Internal server error {'non_field_errors': ["HTTPSConnectionPool(host='verify.twilio.com', port=443): Max retries exceeded with url: /v2/Services/VA728c2772f8bd5c83e836c793abe72be3/VerificationCheck (Caused by NewConnectionError('<urllib3.connection.HTTPSConnection object at 0x7f4b57ccac70>: Failed to establish a new connection: [Errno -3] Temporary failure in name resolution'))"]} None
2021-12-29 18:29:37,577 DEBUG rest_utils.py:build_response:78  Response: 200 OK 500 Internal server error {'non_field_errors': ["HTTPSConnectionPool(host='verify.twilio.com', port=443): Max retries exceeded with url: /v2/Services/VA728c2772f8bd5c83e836c793abe72be3/VerificationCheck (Caused by NewConnectionError('<urllib3.connection.HTTPSConnection object at 0x7f4b57ccac70>: Failed to establish a new connection: [Errno -3] Temporary failure in name resolution'))"]} None
2021-12-29 18:30:04,885 ERROR rest_utils.py:build_response:61  Response: 500 Internal server error {'non_field_errors': ['.validate() should return the validated data']} None
2021-12-29 18:30:04,886 DEBUG rest_utils.py:build_response:78  Response: 200 OK 500 Internal server error {'non_field_errors': ['.validate() should return the validated data']} None
2021-12-29 18:30:51,789 ERROR rest_utils.py:build_response:61  Response: 500 Internal server error {'non_field_errors': ['.validate() should return the validated data']} None
2021-12-29 18:30:51,790 DEBUG rest_utils.py:build_response:78  Response: 200 OK 500 Internal server error {'non_field_errors': ['.validate() should return the validated data']} None
2021-12-29 18:31:24,990 ERROR rest_utils.py:build_response:61  Response: 500 Internal server error {'non_field_errors': ["HTTPSConnectionPool(host='verify.twilio.com', port=443): Max retries exceeded with url: /v2/Services/VA728c2772f8bd5c83e836c793abe72be3/VerificationCheck (Caused by NewConnectionError('<urllib3.connection.HTTPSConnection object at 0x7fcd2106b0a0>: Failed to establish a new connection: [Errno -3] Temporary failure in name resolution'))"]} None
2021-12-29 18:31:24,991 DEBUG rest_utils.py:build_response:78  Response: 200 OK 500 Internal server error {'non_field_errors': ["HTTPSConnectionPool(host='verify.twilio.com', port=443): Max retries exceeded with url: /v2/Services/VA728c2772f8bd5c83e836c793abe72be3/VerificationCheck (Caused by NewConnectionError('<urllib3.connection.HTTPSConnection object at 0x7fcd2106b0a0>: Failed to establish a new connection: [Errno -3] Temporary failure in name resolution'))"]} None
2021-12-29 18:31:25,893 ERROR rest_utils.py:build_response:61  Response: 500 Internal server error {'non_field_errors': ["HTTPSConnectionPool(host='verify.twilio.com', port=443): Max retries exceeded with url: /v2/Services/VA728c2772f8bd5c83e836c793abe72be3/VerificationCheck (Caused by NewConnectionError('<urllib3.connection.HTTPSConnection object at 0x7fcd2066fdc0>: Failed to establish a new connection: [Errno -3] Temporary failure in name resolution'))"]} None
2021-12-29 18:31:25,893 DEBUG rest_utils.py:build_response:78  Response: 200 OK 500 Internal server error {'non_field_errors': ["HTTPSConnectionPool(host='verify.twilio.com', port=443): Max retries exceeded with url: /v2/Services/VA728c2772f8bd5c83e836c793abe72be3/VerificationCheck (Caused by NewConnectionError('<urllib3.connection.HTTPSConnection object at 0x7fcd2066fdc0>: Failed to establish a new connection: [Errno -3] Temporary failure in name resolution'))"]} None
2021-12-29 18:31:29,300 ERROR rest_utils.py:build_response:61  Response: 500 Internal server error {'non_field_errors': ["HTTPSConnectionPool(host='verify.twilio.com', port=443): Max retries exceeded with url: /v2/Services/VA728c2772f8bd5c83e836c793abe72be3/VerificationCheck (Caused by NewConnectionError('<urllib3.connection.HTTPSConnection object at 0x7fcd20671310>: Failed to establish a new connection: [Errno -3] Temporary failure in name resolution'))"]} None
2021-12-29 18:31:29,301 DEBUG rest_utils.py:build_response:78  Response: 200 OK 500 Internal server error {'non_field_errors': ["HTTPSConnectionPool(host='verify.twilio.com', port=443): Max retries exceeded with url: /v2/Services/VA728c2772f8bd5c83e836c793abe72be3/VerificationCheck (Caused by NewConnectionError('<urllib3.connection.HTTPSConnection object at 0x7fcd20671310>: Failed to establish a new connection: [Errno -3] Temporary failure in name resolution'))"]} None
2021-12-29 18:31:30,514 ERROR rest_utils.py:build_response:61  Response: 500 Internal server error {'non_field_errors': ["HTTPSConnectionPool(host='verify.twilio.com', port=443): Max retries exceeded with url: /v2/Services/VA728c2772f8bd5c83e836c793abe72be3/VerificationCheck (Caused by NewConnectionError('<urllib3.connection.HTTPSConnection object at 0x7fcd20633730>: Failed to establish a new connection: [Errno -3] Temporary failure in name resolution'))"]} None
2021-12-29 18:31:30,514 DEBUG rest_utils.py:build_response:78  Response: 200 OK 500 Internal server error {'non_field_errors': ["HTTPSConnectionPool(host='verify.twilio.com', port=443): Max retries exceeded with url: /v2/Services/VA728c2772f8bd5c83e836c793abe72be3/VerificationCheck (Caused by NewConnectionError('<urllib3.connection.HTTPSConnection object at 0x7fcd20633730>: Failed to establish a new connection: [Errno -3] Temporary failure in name resolution'))"]} None
2021-12-29 18:31:31,900 ERROR rest_utils.py:build_response:61  Response: 500 Internal server error {'non_field_errors': ["HTTPSConnectionPool(host='verify.twilio.com', port=443): Max retries exceeded with url: /v2/Services/VA728c2772f8bd5c83e836c793abe72be3/VerificationCheck (Caused by NewConnectionError('<urllib3.connection.HTTPSConnection object at 0x7fcd206a6a00>: Failed to establish a new connection: [Errno -3] Temporary failure in name resolution'))"]} None
2021-12-29 18:31:31,900 DEBUG rest_utils.py:build_response:78  Response: 200 OK 500 Internal server error {'non_field_errors': ["HTTPSConnectionPool(host='verify.twilio.com', port=443): Max retries exceeded with url: /v2/Services/VA728c2772f8bd5c83e836c793abe72be3/VerificationCheck (Caused by NewConnectionError('<urllib3.connection.HTTPSConnection object at 0x7fcd206a6a00>: Failed to establish a new connection: [Errno -3] Temporary failure in name resolution'))"]} None
2021-12-29 18:31:50,490 ERROR rest_utils.py:build_response:61  Response: 500 Internal server error {'non_field_errors': ["HTTPSConnectionPool(host='verify.twilio.com', port=443): Max retries exceeded with url: /v2/Services/VA728c2772f8bd5c83e836c793abe72be3/VerificationCheck (Caused by NewConnectionError('<urllib3.connection.HTTPSConnection object at 0x7fcd20784910>: Failed to establish a new connection: [Errno -3] Temporary failure in name resolution'))"]} None
2021-12-29 18:31:50,490 DEBUG rest_utils.py:build_response:78  Response: 200 OK 500 Internal server error {'non_field_errors': ["HTTPSConnectionPool(host='verify.twilio.com', port=443): Max retries exceeded with url: /v2/Services/VA728c2772f8bd5c83e836c793abe72be3/VerificationCheck (Caused by NewConnectionError('<urllib3.connection.HTTPSConnection object at 0x7fcd20784910>: Failed to establish a new connection: [Errno -3] Temporary failure in name resolution'))"]} None
2021-12-29 18:31:51,511 ERROR rest_utils.py:build_response:61  Response: 500 Internal server error {'non_field_errors': ["HTTPSConnectionPool(host='verify.twilio.com', port=443): Max retries exceeded with url: /v2/Services/VA728c2772f8bd5c83e836c793abe72be3/VerificationCheck (Caused by NewConnectionError('<urllib3.connection.HTTPSConnection object at 0x7fcd2062d070>: Failed to establish a new connection: [Errno -3] Temporary failure in name resolution'))"]} None
2021-12-29 18:31:51,511 DEBUG rest_utils.py:build_response:78  Response: 200 OK 500 Internal server error {'non_field_errors': ["HTTPSConnectionPool(host='verify.twilio.com', port=443): Max retries exceeded with url: /v2/Services/VA728c2772f8bd5c83e836c793abe72be3/VerificationCheck (Caused by NewConnectionError('<urllib3.connection.HTTPSConnection object at 0x7fcd2062d070>: Failed to establish a new connection: [Errno -3] Temporary failure in name resolution'))"]} None
2021-12-29 18:31:55,079 ERROR rest_utils.py:build_response:61  Response: 500 Internal server error {'non_field_errors': ["HTTPSConnectionPool(host='verify.twilio.com', port=443): Max retries exceeded with url: /v2/Services/VA728c2772f8bd5c83e836c793abe72be3/VerificationCheck (Caused by NewConnectionError('<urllib3.connection.HTTPSConnection object at 0x7fcd206e8640>: Failed to establish a new connection: [Errno -3] Temporary failure in name resolution'))"]} None
2021-12-29 18:31:55,079 DEBUG rest_utils.py:build_response:78  Response: 200 OK 500 Internal server error {'non_field_errors': ["HTTPSConnectionPool(host='verify.twilio.com', port=443): Max retries exceeded with url: /v2/Services/VA728c2772f8bd5c83e836c793abe72be3/VerificationCheck (Caused by NewConnectionError('<urllib3.connection.HTTPSConnection object at 0x7fcd206e8640>: Failed to establish a new connection: [Errno -3] Temporary failure in name resolution'))"]} None
2021-12-29 18:31:56,064 ERROR rest_utils.py:build_response:61  Response: 500 Internal server error {'non_field_errors': ["HTTPSConnectionPool(host='verify.twilio.com', port=443): Max retries exceeded with url: /v2/Services/VA728c2772f8bd5c83e836c793abe72be3/VerificationCheck (Caused by NewConnectionError('<urllib3.connection.HTTPSConnection object at 0x7fcd208064c0>: Failed to establish a new connection: [Errno -3] Temporary failure in name resolution'))"]} None
2021-12-29 18:31:56,064 DEBUG rest_utils.py:build_response:78  Response: 200 OK 500 Internal server error {'non_field_errors': ["HTTPSConnectionPool(host='verify.twilio.com', port=443): Max retries exceeded with url: /v2/Services/VA728c2772f8bd5c83e836c793abe72be3/VerificationCheck (Caused by NewConnectionError('<urllib3.connection.HTTPSConnection object at 0x7fcd208064c0>: Failed to establish a new connection: [Errno -3] Temporary failure in name resolution'))"]} None
2021-12-29 18:32:01,924 ERROR rest_utils.py:build_response:61  Response: 500 Internal server error {'non_field_errors': ["HTTPSConnectionPool(host='verify.twilio.com', port=443): Max retries exceeded with url: /v2/Services/VA728c2772f8bd5c83e836c793abe72be3/VerificationCheck (Caused by NewConnectionError('<urllib3.connection.HTTPSConnection object at 0x7fcd206d5ca0>: Failed to establish a new connection: [Errno -3] Temporary failure in name resolution'))"]} None
2021-12-29 18:32:01,925 DEBUG rest_utils.py:build_response:78  Response: 200 OK 500 Internal server error {'non_field_errors': ["HTTPSConnectionPool(host='verify.twilio.com', port=443): Max retries exceeded with url: /v2/Services/VA728c2772f8bd5c83e836c793abe72be3/VerificationCheck (Caused by NewConnectionError('<urllib3.connection.HTTPSConnection object at 0x7fcd206d5ca0>: Failed to establish a new connection: [Errno -3] Temporary failure in name resolution'))"]} None
2021-12-29 18:32:49,424 ERROR rest_utils.py:build_response:61  Response: 500 Internal server error {'non_field_errors': ['.validate() should return the validated data']} None
2021-12-29 18:32:49,425 DEBUG rest_utils.py:build_response:78  Response: 200 OK 500 Internal server error {'non_field_errors': ['.validate() should return the validated data']} None
2021-12-29 18:33:55,096 ERROR rest_utils.py:build_response:61  Response: 500 Internal server error {'non_field_errors': ["HTTPSConnectionPool(host='verify.twilio.com', port=443): Max retries exceeded with url: /v2/Services/VA728c2772f8bd5c83e836c793abe72be3/VerificationCheck (Caused by NewConnectionError('<urllib3.connection.HTTPSConnection object at 0x7f55b95a1340>: Failed to establish a new connection: [Errno -3] Temporary failure in name resolution'))"]} None
2021-12-29 18:33:55,097 DEBUG rest_utils.py:build_response:78  Response: 200 OK 500 Internal server error {'non_field_errors': ["HTTPSConnectionPool(host='verify.twilio.com', port=443): Max retries exceeded with url: /v2/Services/VA728c2772f8bd5c83e836c793abe72be3/VerificationCheck (Caused by NewConnectionError('<urllib3.connection.HTTPSConnection object at 0x7f55b95a1340>: Failed to establish a new connection: [Errno -3] Temporary failure in name resolution'))"]} None
2021-12-29 18:34:15,857 ERROR rest_utils.py:build_response:61  Response: 500 Internal server error {'non_field_errors': ['.validate() should return the validated data']} None
2021-12-29 18:34:15,858 DEBUG rest_utils.py:build_response:78  Response: 200 OK 500 Internal server error {'non_field_errors': ['.validate() should return the validated data']} None
2021-12-29 18:35:41,459 DEBUG rest_utils.py:build_response:78  Response: 200 OK 200 User Successfully Login None None
2021-12-29 18:36:37,095 DEBUG rest_utils.py:build_response:78  Response: 200 OK 200 User Successfully Login None None
2021-12-29 18:37:55,122 ERROR rest_utils.py:build_response:61  Response: 500 Internal server error {'non_field_errors': ["HTTPSConnectionPool(host='verify.twilio.com', port=443): Max retries exceeded with url: /v2/Services/VA728c2772f8bd5c83e836c793abe72be3/VerificationCheck (Caused by NewConnectionError('<urllib3.connection.HTTPSConnection object at 0x7f19c34b7250>: Failed to establish a new connection: [Errno -3] Temporary failure in name resolution'))"]} None
2021-12-29 18:37:55,122 DEBUG rest_utils.py:build_response:78  Response: 200 OK 500 Internal server error {'non_field_errors': ["HTTPSConnectionPool(host='verify.twilio.com', port=443): Max retries exceeded with url: /v2/Services/VA728c2772f8bd5c83e836c793abe72be3/VerificationCheck (Caused by NewConnectionError('<urllib3.connection.HTTPSConnection object at 0x7f19c34b7250>: Failed to establish a new connection: [Errno -3] Temporary failure in name resolution'))"]} None
2021-12-29 18:38:08,758 DEBUG rest_utils.py:build_response:78  Response: 200 OK 200 User Successfully Login None None
2021-12-29 18:38:09,976 DEBUG rest_utils.py:build_response:78  Response: 200 OK 200 User Successfully Login None None
2021-12-29 18:39:10,977 DEBUG rest_utils.py:build_response:78  Response: 200 OK 200 User Successfully Login None None
