2022-01-03 15:57:47,315 DEBUG rest_utils.py:build_response:78  Response: 200 OK 200 User OTP successfully send None None
2022-01-03 15:58:24,042 ERROR rest_utils.py:build_response:61  Response: 500 Internal server error {'non_field_errors': ["name 'user' is not defined"]} None
2022-01-03 15:58:24,042 DEBUG rest_utils.py:build_response:78  Response: 200 OK 500 Internal server error {'non_field_errors': ["name 'user' is not defined"]} None
2022-01-03 15:59:03,161 ERROR rest_utils.py:build_response:61  Response: 400 Failed {'non_field_errors': [ErrorDetail(string='Invalid OTP', code='invalid')]} None
2022-01-03 15:59:03,162 DEBUG rest_utils.py:build_response:78  Response: 200 OK 400 Failed {'non_field_errors': [ErrorDetail(string='Invalid OTP', code='invalid')]} None
2022-01-03 15:59:55,530 DEBUG rest_utils.py:build_response:78  Response: 200 OK 200 User OTP successfully send None None
2022-01-03 16:04:40,932 ERROR rest_utils.py:build_response:61  Response: 400 Failed {'non_field_errors': [ErrorDetail(string='Invalid OTP', code='invalid')]} None
2022-01-03 16:04:40,933 DEBUG rest_utils.py:build_response:78  Response: 200 OK 400 Failed {'non_field_errors': [ErrorDetail(string='Invalid OTP', code='invalid')]} None
2022-01-03 16:05:17,331 ERROR rest_utils.py:build_response:61  Response: 400 Failed {'non_field_errors': [ErrorDetail(string='Invalid OTP', code='invalid')]} None
2022-01-03 16:05:17,331 DEBUG rest_utils.py:build_response:78  Response: 200 OK 400 Failed {'non_field_errors': [ErrorDetail(string='Invalid OTP', code='invalid')]} None
2022-01-03 16:05:17,983 ERROR rest_utils.py:build_response:61  Response: 400 Failed {'non_field_errors': [ErrorDetail(string='Invalid OTP', code='invalid')]} None
2022-01-03 16:05:17,984 DEBUG rest_utils.py:build_response:78  Response: 200 OK 400 Failed {'non_field_errors': [ErrorDetail(string='Invalid OTP', code='invalid')]} None
2022-01-03 16:06:09,097 ERROR rest_utils.py:build_response:61  Response: 400 Failed {'non_field_errors': [ErrorDetail(string='Invalid OTP', code='invalid')]} None
2022-01-03 16:06:09,098 DEBUG rest_utils.py:build_response:78  Response: 200 OK 400 Failed {'non_field_errors': [ErrorDetail(string='Invalid OTP', code='invalid')]} None
2022-01-03 16:06:54,509 DEBUG rest_utils.py:build_response:78  Response: 200 OK 200 User OTP successfully send None None
2022-01-03 16:10:41,044 ERROR rest_utils.py:build_response:61  Response: 500 Internal server error {'non_field_errors': ["[ErrorDetail(string='Invalid OTP', code='invalid')]"]} None
2022-01-03 16:10:41,044 DEBUG rest_utils.py:build_response:78  Response: 200 OK 500 Internal server error {'non_field_errors': ["[ErrorDetail(string='Invalid OTP', code='invalid')]"]} None
2022-01-03 16:11:22,139 ERROR rest_utils.py:build_response:61  Response: 400 Failed {'contact': [ErrorDetail(string='This field is required.', code='required')]} None
2022-01-03 16:11:22,140 DEBUG rest_utils.py:build_response:78  Response: 200 OK 400 Failed {'contact': [ErrorDetail(string='This field is required.', code='required')]} None
2022-01-03 16:11:47,957 DEBUG rest_utils.py:build_response:78  Response: 200 OK 200 User OTP successfully send None None
2022-01-03 16:12:21,555 ERROR rest_utils.py:build_response:61  Response: 500 Internal server error {'non_field_errors': ["name 'user' is not defined"]} None
2022-01-03 16:12:21,555 DEBUG rest_utils.py:build_response:78  Response: 200 OK 500 Internal server error {'non_field_errors': ["name 'user' is not defined"]} None
2022-01-03 16:13:24,219 ERROR rest_utils.py:build_response:61  Response: 400 Failed {'non_field_errors': [ErrorDetail(string='Invalid OTP', code='invalid')]} None
2022-01-03 16:13:24,219 DEBUG rest_utils.py:build_response:78  Response: 200 OK 400 Failed {'non_field_errors': [ErrorDetail(string='Invalid OTP', code='invalid')]} None
2022-01-03 16:13:58,059 ERROR rest_utils.py:build_response:61  Response: 500 Internal server error {'non_field_errors': ['Got a `TypeError` when calling `User.objects.create()`. This may be because you have a writable field on the serializer class that is not a valid argument to `User.objects.create()`. You may need to make the field read-only, or override the RegisterSerializer.create() method to handle this correctly.\nOriginal exception was:\n Traceback (most recent call last):\n  File "/home/deep/Live-Projects/snv_backend/snv/env/lib/python3.9/site-packages/rest_framework/serializers.py", line 962, in create\n    instance = ModelClass._default_manager.create(**validated_data)\n  File "/home/deep/Live-Projects/snv_backend/snv/env/lib/python3.9/site-packages/django/db/models/manager.py", line 85, in manager_method\n    return getattr(self.get_queryset(), name)(*args, **kwargs)\n  File "/home/deep/Live-Projects/snv_backend/snv/env/lib/python3.9/site-packages/django/db/models/query.py", line 455, in create\n    obj = self.model(**kwargs)\n  File "/home/deep/Live-Projects/snv_backend/snv/env/lib/python3.9/site-packages/django/db/models/base.py", line 507, in __init__\n    raise TypeError("%s() got an unexpected keyword argument \'%s\'" % (cls.__name__, kwarg))\nTypeError: User() got an unexpected keyword argument \'otp\'\n']} None
2022-01-03 16:13:58,060 DEBUG rest_utils.py:build_response:78  Response: 200 OK 500 Internal server error {'non_field_errors': ['Got a `TypeError` when calling `User.objects.create()`. This may be because you have a writable field on the serializer class that is not a valid argument to `User.objects.create()`. You may need to make the field read-only, or override the RegisterSerializer.create() method to handle this correctly.\nOriginal exception was:\n Traceback (most recent call last):\n  File "/home/deep/Live-Projects/snv_backend/snv/env/lib/python3.9/site-packages/rest_framework/serializers.py", line 962, in create\n    instance = ModelClass._default_manager.create(**validated_data)\n  File "/home/deep/Live-Projects/snv_backend/snv/env/lib/python3.9/site-packages/django/db/models/manager.py", line 85, in manager_method\n    return getattr(self.get_queryset(), name)(*args, **kwargs)\n  File "/home/deep/Live-Projects/snv_backend/snv/env/lib/python3.9/site-packages/django/db/models/query.py", line 455, in create\n    obj = self.model(**kwargs)\n  File "/home/deep/Live-Projects/snv_backend/snv/env/lib/python3.9/site-packages/django/db/models/base.py", line 507, in __init__\n    raise TypeError("%s() got an unexpected keyword argument \'%s\'" % (cls.__name__, kwarg))\nTypeError: User() got an unexpected keyword argument \'otp\'\n']} None
2022-01-03 16:14:52,826 ERROR rest_utils.py:build_response:61  Response: 500 Internal server error {'non_field_errors': ["The field 'otp' was declared on serializer RegisterSerializer, but has not been included in the 'fields' option."]} None
2022-01-03 16:14:52,826 DEBUG rest_utils.py:build_response:78  Response: 200 OK 500 Internal server error {'non_field_errors': ["The field 'otp' was declared on serializer RegisterSerializer, but has not been included in the 'fields' option."]} None
2022-01-03 16:15:30,195 ERROR rest_utils.py:build_response:61  Response: 500 Internal server error {'non_field_errors': ['Got a `TypeError` when calling `User.objects.create()`. This may be because you have a writable field on the serializer class that is not a valid argument to `User.objects.create()`. You may need to make the field read-only, or override the RegisterSerializer.create() method to handle this correctly.\nOriginal exception was:\n Traceback (most recent call last):\n  File "/home/deep/Live-Projects/snv_backend/snv/env/lib/python3.9/site-packages/rest_framework/serializers.py", line 962, in create\n    instance = ModelClass._default_manager.create(**validated_data)\n  File "/home/deep/Live-Projects/snv_backend/snv/env/lib/python3.9/site-packages/django/db/models/manager.py", line 85, in manager_method\n    return getattr(self.get_queryset(), name)(*args, **kwargs)\n  File "/home/deep/Live-Projects/snv_backend/snv/env/lib/python3.9/site-packages/django/db/models/query.py", line 455, in create\n    obj = self.model(**kwargs)\n  File "/home/deep/Live-Projects/snv_backend/snv/env/lib/python3.9/site-packages/django/db/models/base.py", line 507, in __init__\n    raise TypeError("%s() got an unexpected keyword argument \'%s\'" % (cls.__name__, kwarg))\nTypeError: User() got an unexpected keyword argument \'otp\'\n']} None
2022-01-03 16:15:30,196 DEBUG rest_utils.py:build_response:78  Response: 200 OK 500 Internal server error {'non_field_errors': ['Got a `TypeError` when calling `User.objects.create()`. This may be because you have a writable field on the serializer class that is not a valid argument to `User.objects.create()`. You may need to make the field read-only, or override the RegisterSerializer.create() method to handle this correctly.\nOriginal exception was:\n Traceback (most recent call last):\n  File "/home/deep/Live-Projects/snv_backend/snv/env/lib/python3.9/site-packages/rest_framework/serializers.py", line 962, in create\n    instance = ModelClass._default_manager.create(**validated_data)\n  File "/home/deep/Live-Projects/snv_backend/snv/env/lib/python3.9/site-packages/django/db/models/manager.py", line 85, in manager_method\n    return getattr(self.get_queryset(), name)(*args, **kwargs)\n  File "/home/deep/Live-Projects/snv_backend/snv/env/lib/python3.9/site-packages/django/db/models/query.py", line 455, in create\n    obj = self.model(**kwargs)\n  File "/home/deep/Live-Projects/snv_backend/snv/env/lib/python3.9/site-packages/django/db/models/base.py", line 507, in __init__\n    raise TypeError("%s() got an unexpected keyword argument \'%s\'" % (cls.__name__, kwarg))\nTypeError: User() got an unexpected keyword argument \'otp\'\n']} None
2022-01-03 16:16:09,306 ERROR rest_utils.py:build_response:61  Response: 500 Internal server error {'non_field_errors': ['Got a `TypeError` when calling `User.objects.create()`. This may be because you have a writable field on the serializer class that is not a valid argument to `User.objects.create()`. You may need to make the field read-only, or override the RegisterSerializer.create() method to handle this correctly.\nOriginal exception was:\n Traceback (most recent call last):\n  File "/home/deep/Live-Projects/snv_backend/snv/env/lib/python3.9/site-packages/rest_framework/serializers.py", line 962, in create\n    instance = ModelClass._default_manager.create(**validated_data)\n  File "/home/deep/Live-Projects/snv_backend/snv/env/lib/python3.9/site-packages/django/db/models/manager.py", line 85, in manager_method\n    return getattr(self.get_queryset(), name)(*args, **kwargs)\n  File "/home/deep/Live-Projects/snv_backend/snv/env/lib/python3.9/site-packages/django/db/models/query.py", line 455, in create\n    obj = self.model(**kwargs)\n  File "/home/deep/Live-Projects/snv_backend/snv/env/lib/python3.9/site-packages/django/db/models/base.py", line 507, in __init__\n    raise TypeError("%s() got an unexpected keyword argument \'%s\'" % (cls.__name__, kwarg))\nTypeError: User() got an unexpected keyword argument \'otp\'\n']} None
2022-01-03 16:16:09,306 DEBUG rest_utils.py:build_response:78  Response: 200 OK 500 Internal server error {'non_field_errors': ['Got a `TypeError` when calling `User.objects.create()`. This may be because you have a writable field on the serializer class that is not a valid argument to `User.objects.create()`. You may need to make the field read-only, or override the RegisterSerializer.create() method to handle this correctly.\nOriginal exception was:\n Traceback (most recent call last):\n  File "/home/deep/Live-Projects/snv_backend/snv/env/lib/python3.9/site-packages/rest_framework/serializers.py", line 962, in create\n    instance = ModelClass._default_manager.create(**validated_data)\n  File "/home/deep/Live-Projects/snv_backend/snv/env/lib/python3.9/site-packages/django/db/models/manager.py", line 85, in manager_method\n    return getattr(self.get_queryset(), name)(*args, **kwargs)\n  File "/home/deep/Live-Projects/snv_backend/snv/env/lib/python3.9/site-packages/django/db/models/query.py", line 455, in create\n    obj = self.model(**kwargs)\n  File "/home/deep/Live-Projects/snv_backend/snv/env/lib/python3.9/site-packages/django/db/models/base.py", line 507, in __init__\n    raise TypeError("%s() got an unexpected keyword argument \'%s\'" % (cls.__name__, kwarg))\nTypeError: User() got an unexpected keyword argument \'otp\'\n']} None
2022-01-03 16:16:10,867 ERROR rest_utils.py:build_response:61  Response: 500 Internal server error {'non_field_errors': ['Got a `TypeError` when calling `User.objects.create()`. This may be because you have a writable field on the serializer class that is not a valid argument to `User.objects.create()`. You may need to make the field read-only, or override the RegisterSerializer.create() method to handle this correctly.\nOriginal exception was:\n Traceback (most recent call last):\n  File "/home/deep/Live-Projects/snv_backend/snv/env/lib/python3.9/site-packages/rest_framework/serializers.py", line 962, in create\n    instance = ModelClass._default_manager.create(**validated_data)\n  File "/home/deep/Live-Projects/snv_backend/snv/env/lib/python3.9/site-packages/django/db/models/manager.py", line 85, in manager_method\n    return getattr(self.get_queryset(), name)(*args, **kwargs)\n  File "/home/deep/Live-Projects/snv_backend/snv/env/lib/python3.9/site-packages/django/db/models/query.py", line 455, in create\n    obj = self.model(**kwargs)\n  File "/home/deep/Live-Projects/snv_backend/snv/env/lib/python3.9/site-packages/django/db/models/base.py", line 507, in __init__\n    raise TypeError("%s() got an unexpected keyword argument \'%s\'" % (cls.__name__, kwarg))\nTypeError: User() got an unexpected keyword argument \'otp\'\n']} None
2022-01-03 16:16:10,868 DEBUG rest_utils.py:build_response:78  Response: 200 OK 500 Internal server error {'non_field_errors': ['Got a `TypeError` when calling `User.objects.create()`. This may be because you have a writable field on the serializer class that is not a valid argument to `User.objects.create()`. You may need to make the field read-only, or override the RegisterSerializer.create() method to handle this correctly.\nOriginal exception was:\n Traceback (most recent call last):\n  File "/home/deep/Live-Projects/snv_backend/snv/env/lib/python3.9/site-packages/rest_framework/serializers.py", line 962, in create\n    instance = ModelClass._default_manager.create(**validated_data)\n  File "/home/deep/Live-Projects/snv_backend/snv/env/lib/python3.9/site-packages/django/db/models/manager.py", line 85, in manager_method\n    return getattr(self.get_queryset(), name)(*args, **kwargs)\n  File "/home/deep/Live-Projects/snv_backend/snv/env/lib/python3.9/site-packages/django/db/models/query.py", line 455, in create\n    obj = self.model(**kwargs)\n  File "/home/deep/Live-Projects/snv_backend/snv/env/lib/python3.9/site-packages/django/db/models/base.py", line 507, in __init__\n    raise TypeError("%s() got an unexpected keyword argument \'%s\'" % (cls.__name__, kwarg))\nTypeError: User() got an unexpected keyword argument \'otp\'\n']} None
2022-01-03 16:16:57,826 ERROR rest_utils.py:build_response:61  Response: 500 Internal server error {'non_field_errors': ['Got a `TypeError` when calling `User.objects.create()`. This may be because you have a writable field on the serializer class that is not a valid argument to `User.objects.create()`. You may need to make the field read-only, or override the RegisterSerializer.create() method to handle this correctly.\nOriginal exception was:\n Traceback (most recent call last):\n  File "/home/deep/Live-Projects/snv_backend/snv/env/lib/python3.9/site-packages/rest_framework/serializers.py", line 962, in create\n    instance = ModelClass._default_manager.create(**validated_data)\n  File "/home/deep/Live-Projects/snv_backend/snv/env/lib/python3.9/site-packages/django/db/models/manager.py", line 85, in manager_method\n    return getattr(self.get_queryset(), name)(*args, **kwargs)\n  File "/home/deep/Live-Projects/snv_backend/snv/env/lib/python3.9/site-packages/django/db/models/query.py", line 455, in create\n    obj = self.model(**kwargs)\n  File "/home/deep/Live-Projects/snv_backend/snv/env/lib/python3.9/site-packages/django/db/models/base.py", line 507, in __init__\n    raise TypeError("%s() got an unexpected keyword argument \'%s\'" % (cls.__name__, kwarg))\nTypeError: User() got an unexpected keyword argument \'otp\'\n']} None
2022-01-03 16:16:57,826 DEBUG rest_utils.py:build_response:78  Response: 200 OK 500 Internal server error {'non_field_errors': ['Got a `TypeError` when calling `User.objects.create()`. This may be because you have a writable field on the serializer class that is not a valid argument to `User.objects.create()`. You may need to make the field read-only, or override the RegisterSerializer.create() method to handle this correctly.\nOriginal exception was:\n Traceback (most recent call last):\n  File "/home/deep/Live-Projects/snv_backend/snv/env/lib/python3.9/site-packages/rest_framework/serializers.py", line 962, in create\n    instance = ModelClass._default_manager.create(**validated_data)\n  File "/home/deep/Live-Projects/snv_backend/snv/env/lib/python3.9/site-packages/django/db/models/manager.py", line 85, in manager_method\n    return getattr(self.get_queryset(), name)(*args, **kwargs)\n  File "/home/deep/Live-Projects/snv_backend/snv/env/lib/python3.9/site-packages/django/db/models/query.py", line 455, in create\n    obj = self.model(**kwargs)\n  File "/home/deep/Live-Projects/snv_backend/snv/env/lib/python3.9/site-packages/django/db/models/base.py", line 507, in __init__\n    raise TypeError("%s() got an unexpected keyword argument \'%s\'" % (cls.__name__, kwarg))\nTypeError: User() got an unexpected keyword argument \'otp\'\n']} None
2022-01-03 16:18:00,796 ERROR rest_utils.py:build_response:61  Response: 500 Internal server error {'non_field_errors': ["'otp'"]} None
2022-01-03 16:18:00,797 DEBUG rest_utils.py:build_response:78  Response: 200 OK 500 Internal server error {'non_field_errors': ["'otp'"]} None
2022-01-03 16:18:40,346 ERROR rest_utils.py:build_response:61  Response: 500 Internal server error {'non_field_errors': ["'otp'"]} None
2022-01-03 16:18:40,347 DEBUG rest_utils.py:build_response:78  Response: 200 OK 500 Internal server error {'non_field_errors': ["'otp'"]} None
2022-01-03 16:19:10,797 ERROR rest_utils.py:build_response:61  Response: 500 Internal server error {'non_field_errors': ["'otp'"]} None
2022-01-03 16:19:10,797 DEBUG rest_utils.py:build_response:78  Response: 200 OK 500 Internal server error {'non_field_errors': ["'otp'"]} None
2022-01-03 16:19:23,704 ERROR rest_utils.py:build_response:61  Response: 500 Internal server error {'non_field_errors': ["'otp'"]} None
2022-01-03 16:19:23,704 DEBUG rest_utils.py:build_response:78  Response: 200 OK 500 Internal server error {'non_field_errors': ["'otp'"]} None
2022-01-03 16:19:24,922 ERROR rest_utils.py:build_response:61  Response: 500 Internal server error {'non_field_errors': ["'otp'"]} None
2022-01-03 16:19:24,923 DEBUG rest_utils.py:build_response:78  Response: 200 OK 500 Internal server error {'non_field_errors': ["'otp'"]} None
2022-01-03 16:19:44,040 ERROR rest_utils.py:build_response:61  Response: 400 Failed {'non_field_errors': [ErrorDetail(string='Invalid OTP', code='invalid')]} None
2022-01-03 16:19:44,041 DEBUG rest_utils.py:build_response:78  Response: 200 OK 400 Failed {'non_field_errors': [ErrorDetail(string='Invalid OTP', code='invalid')]} None
2022-01-03 16:19:55,321 ERROR rest_utils.py:build_response:61  Response: 500 Internal server error {'non_field_errors': ['Got a `TypeError` when calling `User.objects.create()`. This may be because you have a writable field on the serializer class that is not a valid argument to `User.objects.create()`. You may need to make the field read-only, or override the RegisterSerializer.create() method to handle this correctly.\nOriginal exception was:\n Traceback (most recent call last):\n  File "/home/deep/Live-Projects/snv_backend/snv/env/lib/python3.9/site-packages/rest_framework/serializers.py", line 962, in create\n    instance = ModelClass._default_manager.create(**validated_data)\n  File "/home/deep/Live-Projects/snv_backend/snv/env/lib/python3.9/site-packages/django/db/models/manager.py", line 85, in manager_method\n    return getattr(self.get_queryset(), name)(*args, **kwargs)\n  File "/home/deep/Live-Projects/snv_backend/snv/env/lib/python3.9/site-packages/django/db/models/query.py", line 455, in create\n    obj = self.model(**kwargs)\n  File "/home/deep/Live-Projects/snv_backend/snv/env/lib/python3.9/site-packages/django/db/models/base.py", line 507, in __init__\n    raise TypeError("%s() got an unexpected keyword argument \'%s\'" % (cls.__name__, kwarg))\nTypeError: User() got an unexpected keyword argument \'otp\'\n']} None
2022-01-03 16:19:55,321 DEBUG rest_utils.py:build_response:78  Response: 200 OK 500 Internal server error {'non_field_errors': ['Got a `TypeError` when calling `User.objects.create()`. This may be because you have a writable field on the serializer class that is not a valid argument to `User.objects.create()`. You may need to make the field read-only, or override the RegisterSerializer.create() method to handle this correctly.\nOriginal exception was:\n Traceback (most recent call last):\n  File "/home/deep/Live-Projects/snv_backend/snv/env/lib/python3.9/site-packages/rest_framework/serializers.py", line 962, in create\n    instance = ModelClass._default_manager.create(**validated_data)\n  File "/home/deep/Live-Projects/snv_backend/snv/env/lib/python3.9/site-packages/django/db/models/manager.py", line 85, in manager_method\n    return getattr(self.get_queryset(), name)(*args, **kwargs)\n  File "/home/deep/Live-Projects/snv_backend/snv/env/lib/python3.9/site-packages/django/db/models/query.py", line 455, in create\n    obj = self.model(**kwargs)\n  File "/home/deep/Live-Projects/snv_backend/snv/env/lib/python3.9/site-packages/django/db/models/base.py", line 507, in __init__\n    raise TypeError("%s() got an unexpected keyword argument \'%s\'" % (cls.__name__, kwarg))\nTypeError: User() got an unexpected keyword argument \'otp\'\n']} None
2022-01-03 16:20:14,896 ERROR rest_utils.py:build_response:61  Response: 500 Internal server error {'non_field_errors': ["'contact'"]} None
2022-01-03 16:20:14,897 DEBUG rest_utils.py:build_response:78  Response: 200 OK 500 Internal server error {'non_field_errors': ["'contact'"]} None
2022-01-03 16:20:47,141 ERROR rest_utils.py:build_response:61  Response: 500 Internal server error {'non_field_errors': ['Got a `TypeError` when calling `User.objects.create()`. This may be because you have a writable field on the serializer class that is not a valid argument to `User.objects.create()`. You may need to make the field read-only, or override the RegisterSerializer.create() method to handle this correctly.\nOriginal exception was:\n Traceback (most recent call last):\n  File "/home/deep/Live-Projects/snv_backend/snv/env/lib/python3.9/site-packages/rest_framework/serializers.py", line 962, in create\n    instance = ModelClass._default_manager.create(**validated_data)\n  File "/home/deep/Live-Projects/snv_backend/snv/env/lib/python3.9/site-packages/django/db/models/manager.py", line 85, in manager_method\n    return getattr(self.get_queryset(), name)(*args, **kwargs)\n  File "/home/deep/Live-Projects/snv_backend/snv/env/lib/python3.9/site-packages/django/db/models/query.py", line 455, in create\n    obj = self.model(**kwargs)\n  File "/home/deep/Live-Projects/snv_backend/snv/env/lib/python3.9/site-packages/django/db/models/base.py", line 507, in __init__\n    raise TypeError("%s() got an unexpected keyword argument \'%s\'" % (cls.__name__, kwarg))\nTypeError: User() got an unexpected keyword argument \'otp\'\n']} None
2022-01-03 16:20:47,141 DEBUG rest_utils.py:build_response:78  Response: 200 OK 500 Internal server error {'non_field_errors': ['Got a `TypeError` when calling `User.objects.create()`. This may be because you have a writable field on the serializer class that is not a valid argument to `User.objects.create()`. You may need to make the field read-only, or override the RegisterSerializer.create() method to handle this correctly.\nOriginal exception was:\n Traceback (most recent call last):\n  File "/home/deep/Live-Projects/snv_backend/snv/env/lib/python3.9/site-packages/rest_framework/serializers.py", line 962, in create\n    instance = ModelClass._default_manager.create(**validated_data)\n  File "/home/deep/Live-Projects/snv_backend/snv/env/lib/python3.9/site-packages/django/db/models/manager.py", line 85, in manager_method\n    return getattr(self.get_queryset(), name)(*args, **kwargs)\n  File "/home/deep/Live-Projects/snv_backend/snv/env/lib/python3.9/site-packages/django/db/models/query.py", line 455, in create\n    obj = self.model(**kwargs)\n  File "/home/deep/Live-Projects/snv_backend/snv/env/lib/python3.9/site-packages/django/db/models/base.py", line 507, in __init__\n    raise TypeError("%s() got an unexpected keyword argument \'%s\'" % (cls.__name__, kwarg))\nTypeError: User() got an unexpected keyword argument \'otp\'\n']} None
2022-01-03 16:21:32,979 ERROR rest_utils.py:build_response:61  Response: 500 Internal server error {'non_field_errors': ['Got a `TypeError` when calling `User.objects.create()`. This may be because you have a writable field on the serializer class that is not a valid argument to `User.objects.create()`. You may need to make the field read-only, or override the RegisterSerializer.create() method to handle this correctly.\nOriginal exception was:\n Traceback (most recent call last):\n  File "/home/deep/Live-Projects/snv_backend/snv/env/lib/python3.9/site-packages/rest_framework/serializers.py", line 962, in create\n    instance = ModelClass._default_manager.create(**validated_data)\n  File "/home/deep/Live-Projects/snv_backend/snv/env/lib/python3.9/site-packages/django/db/models/manager.py", line 85, in manager_method\n    return getattr(self.get_queryset(), name)(*args, **kwargs)\n  File "/home/deep/Live-Projects/snv_backend/snv/env/lib/python3.9/site-packages/django/db/models/query.py", line 455, in create\n    obj = self.model(**kwargs)\n  File "/home/deep/Live-Projects/snv_backend/snv/env/lib/python3.9/site-packages/django/db/models/base.py", line 507, in __init__\n    raise TypeError("%s() got an unexpected keyword argument \'%s\'" % (cls.__name__, kwarg))\nTypeError: User() got an unexpected keyword argument \'otp\'\n']} None
2022-01-03 16:21:32,979 DEBUG rest_utils.py:build_response:78  Response: 200 OK 500 Internal server error {'non_field_errors': ['Got a `TypeError` when calling `User.objects.create()`. This may be because you have a writable field on the serializer class that is not a valid argument to `User.objects.create()`. You may need to make the field read-only, or override the RegisterSerializer.create() method to handle this correctly.\nOriginal exception was:\n Traceback (most recent call last):\n  File "/home/deep/Live-Projects/snv_backend/snv/env/lib/python3.9/site-packages/rest_framework/serializers.py", line 962, in create\n    instance = ModelClass._default_manager.create(**validated_data)\n  File "/home/deep/Live-Projects/snv_backend/snv/env/lib/python3.9/site-packages/django/db/models/manager.py", line 85, in manager_method\n    return getattr(self.get_queryset(), name)(*args, **kwargs)\n  File "/home/deep/Live-Projects/snv_backend/snv/env/lib/python3.9/site-packages/django/db/models/query.py", line 455, in create\n    obj = self.model(**kwargs)\n  File "/home/deep/Live-Projects/snv_backend/snv/env/lib/python3.9/site-packages/django/db/models/base.py", line 507, in __init__\n    raise TypeError("%s() got an unexpected keyword argument \'%s\'" % (cls.__name__, kwarg))\nTypeError: User() got an unexpected keyword argument \'otp\'\n']} None
2022-01-03 16:23:09,209 ERROR rest_utils.py:build_response:61  Response: 500 Internal server error {'non_field_errors': ["[ErrorDetail(string='Invalid OTP', code='invalid')]"]} None
2022-01-03 16:23:09,209 DEBUG rest_utils.py:build_response:78  Response: 200 OK 500 Internal server error {'non_field_errors': ["[ErrorDetail(string='Invalid OTP', code='invalid')]"]} None
2022-01-03 16:25:31,101 ERROR rest_utils.py:build_response:61  Response: 500 Internal server error {'non_field_errors': ["[ErrorDetail(string='Invalid OTP', code='invalid')]"]} None
2022-01-03 16:25:31,101 DEBUG rest_utils.py:build_response:78  Response: 200 OK 500 Internal server error {'non_field_errors': ["[ErrorDetail(string='Invalid OTP', code='invalid')]"]} None
2022-01-03 16:25:59,432 DEBUG rest_utils.py:build_response:78  Response: 200 OK 200 User created successfully None None
2022-01-03 16:26:04,200 ERROR rest_utils.py:build_response:61  Response: 400 Failed {'non_field_errors': [ErrorDetail(string='This contact Number Already Exits', code='invalid')]} None
2022-01-03 16:26:04,201 DEBUG rest_utils.py:build_response:78  Response: 200 OK 400 Failed {'non_field_errors': [ErrorDetail(string='This contact Number Already Exits', code='invalid')]} None
2022-01-03 16:27:09,965 ERROR rest_utils.py:build_response:61  Response: 400 Failed {'non_field_errors': [ErrorDetail(string='Invalid OTP', code='invalid')]} None
2022-01-03 16:27:09,965 DEBUG rest_utils.py:build_response:78  Response: 200 OK 400 Failed {'non_field_errors': [ErrorDetail(string='Invalid OTP', code='invalid')]} None
2022-01-03 16:28:30,235 DEBUG rest_utils.py:build_response:78  Response: 200 OK 200 User OTP successfully send None None
2022-01-03 16:28:55,814 ERROR rest_utils.py:build_response:61  Response: 500 Internal server error {'non_field_errors': ["name 'user' is not defined"]} None
2022-01-03 16:28:55,814 DEBUG rest_utils.py:build_response:78  Response: 200 OK 500 Internal server error {'non_field_errors': ["name 'user' is not defined"]} None
2022-01-03 16:30:12,186 ERROR rest_utils.py:build_response:61  Response: 400 Failed {'non_field_errors': [ErrorDetail(string='Invalid OTP', code='invalid')]} None
2022-01-03 16:30:12,187 DEBUG rest_utils.py:build_response:78  Response: 200 OK 400 Failed {'non_field_errors': [ErrorDetail(string='Invalid OTP', code='invalid')]} None
2022-01-03 16:30:34,713 DEBUG rest_utils.py:build_response:78  Response: 200 OK 200 User OTP successfully send None None
2022-01-03 16:30:55,399 ERROR rest_utils.py:build_response:61  Response: 500 Internal server error {'non_field_errors': ["name 'user' is not defined"]} None
2022-01-03 16:30:55,399 DEBUG rest_utils.py:build_response:78  Response: 200 OK 500 Internal server error {'non_field_errors': ["name 'user' is not defined"]} None
2022-01-03 16:32:15,573 ERROR rest_utils.py:build_response:61  Response: 400 Failed {'non_field_errors': [ErrorDetail(string='Invalid OTP', code='invalid')]} None
2022-01-03 16:32:15,573 DEBUG rest_utils.py:build_response:78  Response: 200 OK 400 Failed {'non_field_errors': [ErrorDetail(string='Invalid OTP', code='invalid')]} None
2022-01-03 16:32:23,771 DEBUG rest_utils.py:build_response:78  Response: 200 OK 200 User OTP successfully send None None
2022-01-03 16:32:45,334 ERROR rest_utils.py:build_response:61  Response: 500 Internal server error {'non_field_errors': ["name 'user' is not defined"]} None
2022-01-03 16:32:45,335 DEBUG rest_utils.py:build_response:78  Response: 200 OK 500 Internal server error {'non_field_errors': ["name 'user' is not defined"]} None
2022-01-03 16:35:08,775 DEBUG rest_utils.py:build_response:78  Response: 200 OK 200 User Successfully Login None None
2022-01-03 16:35:23,284 DEBUG rest_utils.py:build_response:78  Response: 200 OK 200 User Successfully Login None None
2022-01-03 16:36:37,005 DEBUG rest_utils.py:build_response:78  Response: 200 OK 200 User OTP successfully send None None
2022-01-03 16:36:55,453 ERROR rest_utils.py:build_response:61  Response: 400 Failed {'non_field_errors': [ErrorDetail(string='Invalid OTP', code='invalid')]} None
2022-01-03 16:36:55,453 DEBUG rest_utils.py:build_response:78  Response: 200 OK 400 Failed {'non_field_errors': [ErrorDetail(string='Invalid OTP', code='invalid')]} None
2022-01-03 16:37:01,150 ERROR rest_utils.py:build_response:61  Response: 400 Failed {'non_field_errors': [ErrorDetail(string='Invalid OTP', code='invalid')]} None
2022-01-03 16:37:01,151 DEBUG rest_utils.py:build_response:78  Response: 200 OK 400 Failed {'non_field_errors': [ErrorDetail(string='Invalid OTP', code='invalid')]} None
2022-01-03 16:37:20,302 DEBUG rest_utils.py:build_response:78  Response: 200 OK 200 User OTP successfully send None None
2022-01-03 16:37:36,050 ERROR rest_utils.py:build_response:61  Response: 400 Failed {'non_field_errors': [ErrorDetail(string='Invalid OTP', code='invalid')]} None
2022-01-03 16:37:36,050 DEBUG rest_utils.py:build_response:78  Response: 200 OK 400 Failed {'non_field_errors': [ErrorDetail(string='Invalid OTP', code='invalid')]} None
2022-01-03 16:37:40,883 ERROR rest_utils.py:build_response:61  Response: 400 Failed {'non_field_errors': [ErrorDetail(string='Invalid OTP', code='invalid')]} None
2022-01-03 16:37:40,883 DEBUG rest_utils.py:build_response:78  Response: 200 OK 400 Failed {'non_field_errors': [ErrorDetail(string='Invalid OTP', code='invalid')]} None
2022-01-03 16:38:10,785 ERROR rest_utils.py:build_response:61  Response: 400 Failed {'non_field_errors': [ErrorDetail(string='Invalid OTP', code='invalid')]} None
2022-01-03 16:38:10,786 DEBUG rest_utils.py:build_response:78  Response: 200 OK 400 Failed {'non_field_errors': [ErrorDetail(string='Invalid OTP', code='invalid')]} None
2022-01-03 16:38:15,622 DEBUG rest_utils.py:build_response:78  Response: 200 OK 200 User OTP successfully send None None
2022-01-03 16:38:39,971 ERROR rest_utils.py:build_response:61  Response: 400 Failed {'non_field_errors': [ErrorDetail(string='Invalid OTP', code='invalid')]} None
2022-01-03 16:38:39,972 DEBUG rest_utils.py:build_response:78  Response: 200 OK 400 Failed {'non_field_errors': [ErrorDetail(string='Invalid OTP', code='invalid')]} None
2022-01-03 16:39:02,235 DEBUG rest_utils.py:build_response:78  Response: 200 OK 200 User OTP successfully send None None
2022-01-03 16:39:19,928 ERROR rest_utils.py:build_response:61  Response: 400 Failed {'non_field_errors': [ErrorDetail(string='Invalid OTP', code='invalid')]} None
2022-01-03 16:39:19,928 DEBUG rest_utils.py:build_response:78  Response: 200 OK 400 Failed {'non_field_errors': [ErrorDetail(string='Invalid OTP', code='invalid')]} None
2022-01-03 16:39:55,771 DEBUG rest_utils.py:build_response:78  Response: 200 OK 200 User OTP successfully send None None
2022-01-03 16:40:12,086 ERROR rest_utils.py:build_response:61  Response: 400 Failed {'non_field_errors': [ErrorDetail(string='Invalid OTP', code='invalid')]} None
2022-01-03 16:40:12,086 DEBUG rest_utils.py:build_response:78  Response: 200 OK 400 Failed {'non_field_errors': [ErrorDetail(string='Invalid OTP', code='invalid')]} None
2022-01-03 16:40:25,144 ERROR rest_utils.py:build_response:61  Response: 400 Failed {'non_field_errors': [ErrorDetail(string='Invalid OTP', code='invalid')]} None
2022-01-03 16:40:25,144 DEBUG rest_utils.py:build_response:78  Response: 200 OK 400 Failed {'non_field_errors': [ErrorDetail(string='Invalid OTP', code='invalid')]} None
2022-01-03 16:44:39,611 ERROR rest_utils.py:build_response:61  Response: 400 
[31m[49mHTTP Error[0m [37m[49mYour request was:[0m

[36m[49mPOST /Services/VA097bdda795cf2519f27764e213ea966a/Verifications[0m

[37m[49mTwilio returned the following information:[0m

[34m[49mUnable to create record: Max send attempts reached[0m

[37m[49mMore information may be available here:[0m

[34m[49mhttps://www.twilio.com/docs/errors/60203[0m

 {'non_field_errors': ['\n\x1b[31m\x1b[49mHTTP Error\x1b[0m \x1b[37m\x1b[49mYour request was:\x1b[0m\n\n\x1b[36m\x1b[49mPOST /Services/VA097bdda795cf2519f27764e213ea966a/Verifications\x1b[0m\n\n\x1b[37m\x1b[49mTwilio returned the following information:\x1b[0m\n\n\x1b[34m\x1b[49mUnable to create record: Max send attempts reached\x1b[0m\n\n\x1b[37m\x1b[49mMore information may be available here:\x1b[0m\n\n\x1b[34m\x1b[49mhttps://www.twilio.com/docs/errors/60203\x1b[0m\n\n']} None
2022-01-03 16:44:39,612 DEBUG rest_utils.py:build_response:78  Response: 200 OK 400 
[31m[49mHTTP Error[0m [37m[49mYour request was:[0m

[36m[49mPOST /Services/VA097bdda795cf2519f27764e213ea966a/Verifications[0m

[37m[49mTwilio returned the following information:[0m

[34m[49mUnable to create record: Max send attempts reached[0m

[37m[49mMore information may be available here:[0m

[34m[49mhttps://www.twilio.com/docs/errors/60203[0m

 {'non_field_errors': ['\n\x1b[31m\x1b[49mHTTP Error\x1b[0m \x1b[37m\x1b[49mYour request was:\x1b[0m\n\n\x1b[36m\x1b[49mPOST /Services/VA097bdda795cf2519f27764e213ea966a/Verifications\x1b[0m\n\n\x1b[37m\x1b[49mTwilio returned the following information:\x1b[0m\n\n\x1b[34m\x1b[49mUnable to create record: Max send attempts reached\x1b[0m\n\n\x1b[37m\x1b[49mMore information may be available here:\x1b[0m\n\n\x1b[34m\x1b[49mhttps://www.twilio.com/docs/errors/60203\x1b[0m\n\n']} None
2022-01-03 16:44:51,130 ERROR rest_utils.py:build_response:61  Response: 400 
[31m[49mHTTP Error[0m [37m[49mYour request was:[0m

[36m[49mPOST /Services/VA097bdda795cf2519f27764e213ea966a/Verifications[0m

[37m[49mTwilio returned the following information:[0m

[34m[49mUnable to create record: Max send attempts reached[0m

[37m[49mMore information may be available here:[0m

[34m[49mhttps://www.twilio.com/docs/errors/60203[0m

 {'non_field_errors': ['\n\x1b[31m\x1b[49mHTTP Error\x1b[0m \x1b[37m\x1b[49mYour request was:\x1b[0m\n\n\x1b[36m\x1b[49mPOST /Services/VA097bdda795cf2519f27764e213ea966a/Verifications\x1b[0m\n\n\x1b[37m\x1b[49mTwilio returned the following information:\x1b[0m\n\n\x1b[34m\x1b[49mUnable to create record: Max send attempts reached\x1b[0m\n\n\x1b[37m\x1b[49mMore information may be available here:\x1b[0m\n\n\x1b[34m\x1b[49mhttps://www.twilio.com/docs/errors/60203\x1b[0m\n\n']} None
2022-01-03 16:44:51,130 DEBUG rest_utils.py:build_response:78  Response: 200 OK 400 
[31m[49mHTTP Error[0m [37m[49mYour request was:[0m

[36m[49mPOST /Services/VA097bdda795cf2519f27764e213ea966a/Verifications[0m

[37m[49mTwilio returned the following information:[0m

[34m[49mUnable to create record: Max send attempts reached[0m

[37m[49mMore information may be available here:[0m

[34m[49mhttps://www.twilio.com/docs/errors/60203[0m

 {'non_field_errors': ['\n\x1b[31m\x1b[49mHTTP Error\x1b[0m \x1b[37m\x1b[49mYour request was:\x1b[0m\n\n\x1b[36m\x1b[49mPOST /Services/VA097bdda795cf2519f27764e213ea966a/Verifications\x1b[0m\n\n\x1b[37m\x1b[49mTwilio returned the following information:\x1b[0m\n\n\x1b[34m\x1b[49mUnable to create record: Max send attempts reached\x1b[0m\n\n\x1b[37m\x1b[49mMore information may be available here:\x1b[0m\n\n\x1b[34m\x1b[49mhttps://www.twilio.com/docs/errors/60203\x1b[0m\n\n']} None
2022-01-03 16:49:21,010 DEBUG rest_utils.py:build_response:78  Response: 200 OK 200 User OTP successfully send None None
2022-01-03 16:49:49,203 ERROR rest_utils.py:build_response:61  Response: 400 Failed {'non_field_errors': [ErrorDetail(string='Invalid OTP', code='invalid')]} None
2022-01-03 16:49:49,204 DEBUG rest_utils.py:build_response:78  Response: 200 OK 400 Failed {'non_field_errors': [ErrorDetail(string='Invalid OTP', code='invalid')]} None
2022-01-03 16:51:16,813 ERROR rest_utils.py:build_response:61  Response: 400 Failed {'non_field_errors': [ErrorDetail(string='Invalid OTP', code='invalid')]} None
2022-01-03 16:51:16,814 DEBUG rest_utils.py:build_response:78  Response: 200 OK 400 Failed {'non_field_errors': [ErrorDetail(string='Invalid OTP', code='invalid')]} None
2022-01-03 16:51:23,004 DEBUG rest_utils.py:build_response:78  Response: 200 OK 200 User OTP successfully send None None
2022-01-03 16:51:56,207 ERROR rest_utils.py:build_response:61  Response: 400 Failed {'non_field_errors': [ErrorDetail(string='Invalid OTP', code='invalid')]} None
2022-01-03 16:51:56,207 DEBUG rest_utils.py:build_response:78  Response: 200 OK 400 Failed {'non_field_errors': [ErrorDetail(string='Invalid OTP', code='invalid')]} None
2022-01-03 16:51:59,289 ERROR rest_utils.py:build_response:61  Response: 400 Failed {'non_field_errors': [ErrorDetail(string='Invalid OTP', code='invalid')]} None
2022-01-03 16:51:59,289 DEBUG rest_utils.py:build_response:78  Response: 200 OK 400 Failed {'non_field_errors': [ErrorDetail(string='Invalid OTP', code='invalid')]} None
2022-01-03 16:52:00,642 ERROR rest_utils.py:build_response:61  Response: 400 Failed {'non_field_errors': [ErrorDetail(string='Invalid OTP', code='invalid')]} None
2022-01-03 16:52:00,642 DEBUG rest_utils.py:build_response:78  Response: 200 OK 400 Failed {'non_field_errors': [ErrorDetail(string='Invalid OTP', code='invalid')]} None
2022-01-03 16:52:07,727 DEBUG rest_utils.py:build_response:78  Response: 200 OK 200 User OTP successfully send None None
2022-01-03 16:52:27,822 ERROR rest_utils.py:build_response:61  Response: 400 Failed {'non_field_errors': [ErrorDetail(string='Invalid OTP', code='invalid')]} None
2022-01-03 16:52:27,822 DEBUG rest_utils.py:build_response:78  Response: 200 OK 400 Failed {'non_field_errors': [ErrorDetail(string='Invalid OTP', code='invalid')]} None
2022-01-03 16:52:44,210 ERROR rest_utils.py:build_response:61  Response: 400 Failed {'non_field_errors': [ErrorDetail(string='Invalid OTP', code='invalid')]} None
2022-01-03 16:52:44,210 DEBUG rest_utils.py:build_response:78  Response: 200 OK 400 Failed {'non_field_errors': [ErrorDetail(string='Invalid OTP', code='invalid')]} None
2022-01-03 16:53:01,278 ERROR rest_utils.py:build_response:61  Response: 400 Failed {'non_field_errors': [ErrorDetail(string='Invalid OTP', code='invalid')]} None
2022-01-03 16:53:01,279 DEBUG rest_utils.py:build_response:78  Response: 200 OK 400 Failed {'non_field_errors': [ErrorDetail(string='Invalid OTP', code='invalid')]} None
2022-01-03 16:55:15,134 DEBUG rest_utils.py:build_response:78  Response: 200 OK 200 User OTP successfully send None None
2022-01-03 16:55:39,698 DEBUG rest_utils.py:build_response:78  Response: 200 OK 200 User Successfully Login None None
2022-01-03 16:59:34,001 DEBUG rest_utils.py:build_response:78  Response: 200 OK 200 User Profile Updated None None
2022-01-03 17:03:22,700 DEBUG rest_utils.py:build_response:78  Response: 200 OK 200 User OTP successfully send None None
2022-01-03 17:03:47,680 DEBUG rest_utils.py:build_response:78  Response: 200 OK 200 User Successfully Login None None
2022-01-03 17:04:16,091 ERROR rest_utils.py:build_response:61  Response: 400 Failed {'username': [ErrorDetail(string='user with this username already exists.', code='unique')]} None
2022-01-03 17:04:16,091 DEBUG rest_utils.py:build_response:78  Response: 200 OK 400 Failed {'username': [ErrorDetail(string='user with this username already exists.', code='unique')]} None
2022-01-03 17:04:25,179 DEBUG rest_utils.py:build_response:78  Response: 200 OK 200 User Profile Updated None None
2022-01-03 17:04:31,490 ERROR rest_utils.py:build_response:61  Response: 500 Internal server error {'non_field_errors': ['User matching query does not exist.']} None
2022-01-03 17:04:31,490 DEBUG rest_utils.py:build_response:78  Response: 200 OK 500 Internal server error {'non_field_errors': ['User matching query does not exist.']} None
2022-01-03 17:04:37,159 DEBUG rest_utils.py:build_response:78  Response: 200 OK 200 User Profile Updated None None
