2021-12-31 12:57:57,445 ERROR rest_utils.py:build_response:61  Response: 400 
[31m[49mHTTP Error[0m [37m[49mYour request was:[0m

[36m[49mPOST /Services/VA3a507dcf4b512600bf6fb565a1bc7c8b/Verifications[0m

[37m[49mTwilio returned the following information:[0m

[34m[49mUnable to create record: Resource not accessible with Test Account Credentials[0m

[37m[49mMore information may be available here:[0m

[34m[49mhttps://www.twilio.com/docs/errors/20008[0m

 {'non_field_errors': ['\n\x1b[31m\x1b[49mHTTP Error\x1b[0m \x1b[37m\x1b[49mYour request was:\x1b[0m\n\n\x1b[36m\x1b[49mPOST /Services/VA3a507dcf4b512600bf6fb565a1bc7c8b/Verifications\x1b[0m\n\n\x1b[37m\x1b[49mTwilio returned the following information:\x1b[0m\n\n\x1b[34m\x1b[49mUnable to create record: Resource not accessible with Test Account Credentials\x1b[0m\n\n\x1b[37m\x1b[49mMore information may be available here:\x1b[0m\n\n\x1b[34m\x1b[49mhttps://www.twilio.com/docs/errors/20008\x1b[0m\n\n']} None
2021-12-31 12:57:57,446 DEBUG rest_utils.py:build_response:78  Response: 200 OK 400 
[31m[49mHTTP Error[0m [37m[49mYour request was:[0m

[36m[49mPOST /Services/VA3a507dcf4b512600bf6fb565a1bc7c8b/Verifications[0m

[37m[49mTwilio returned the following information:[0m

[34m[49mUnable to create record: Resource not accessible with Test Account Credentials[0m

[37m[49mMore information may be available here:[0m

[34m[49mhttps://www.twilio.com/docs/errors/20008[0m

 {'non_field_errors': ['\n\x1b[31m\x1b[49mHTTP Error\x1b[0m \x1b[37m\x1b[49mYour request was:\x1b[0m\n\n\x1b[36m\x1b[49mPOST /Services/VA3a507dcf4b512600bf6fb565a1bc7c8b/Verifications\x1b[0m\n\n\x1b[37m\x1b[49mTwilio returned the following information:\x1b[0m\n\n\x1b[34m\x1b[49mUnable to create record: Resource not accessible with Test Account Credentials\x1b[0m\n\n\x1b[37m\x1b[49mMore information may be available here:\x1b[0m\n\n\x1b[34m\x1b[49mhttps://www.twilio.com/docs/errors/20008\x1b[0m\n\n']} None
2021-12-31 12:58:25,769 ERROR rest_utils.py:build_response:61  Response: 400 
[31m[49mHTTP Error[0m [37m[49mYour request was:[0m

[36m[49mPOST /Services/VA3a507dcf4b512600bf6fb565a1bc7c8b/Verifications[0m

[37m[49mTwilio returned the following information:[0m

[34m[49mUnable to create record: Resource not accessible with Test Account Credentials[0m

[37m[49mMore information may be available here:[0m

[34m[49mhttps://www.twilio.com/docs/errors/20008[0m

 {'non_field_errors': ['\n\x1b[31m\x1b[49mHTTP Error\x1b[0m \x1b[37m\x1b[49mYour request was:\x1b[0m\n\n\x1b[36m\x1b[49mPOST /Services/VA3a507dcf4b512600bf6fb565a1bc7c8b/Verifications\x1b[0m\n\n\x1b[37m\x1b[49mTwilio returned the following information:\x1b[0m\n\n\x1b[34m\x1b[49mUnable to create record: Resource not accessible with Test Account Credentials\x1b[0m\n\n\x1b[37m\x1b[49mMore information may be available here:\x1b[0m\n\n\x1b[34m\x1b[49mhttps://www.twilio.com/docs/errors/20008\x1b[0m\n\n']} None
2021-12-31 12:58:25,770 DEBUG rest_utils.py:build_response:78  Response: 200 OK 400 
[31m[49mHTTP Error[0m [37m[49mYour request was:[0m

[36m[49mPOST /Services/VA3a507dcf4b512600bf6fb565a1bc7c8b/Verifications[0m

[37m[49mTwilio returned the following information:[0m

[34m[49mUnable to create record: Resource not accessible with Test Account Credentials[0m

[37m[49mMore information may be available here:[0m

[34m[49mhttps://www.twilio.com/docs/errors/20008[0m

 {'non_field_errors': ['\n\x1b[31m\x1b[49mHTTP Error\x1b[0m \x1b[37m\x1b[49mYour request was:\x1b[0m\n\n\x1b[36m\x1b[49mPOST /Services/VA3a507dcf4b512600bf6fb565a1bc7c8b/Verifications\x1b[0m\n\n\x1b[37m\x1b[49mTwilio returned the following information:\x1b[0m\n\n\x1b[34m\x1b[49mUnable to create record: Resource not accessible with Test Account Credentials\x1b[0m\n\n\x1b[37m\x1b[49mMore information may be available here:\x1b[0m\n\n\x1b[34m\x1b[49mhttps://www.twilio.com/docs/errors/20008\x1b[0m\n\n']} None
2021-12-31 12:58:34,369 ERROR rest_utils.py:build_response:61  Response: 400 
[31m[49mHTTP Error[0m [37m[49mYour request was:[0m

[36m[49mPOST /Services/VA3a507dcf4b512600bf6fb565a1bc7c8b/Verifications[0m

[37m[49mTwilio returned the following information:[0m

[34m[49mUnable to create record: Resource not accessible with Test Account Credentials[0m

[37m[49mMore information may be available here:[0m

[34m[49mhttps://www.twilio.com/docs/errors/20008[0m

 {'non_field_errors': ['\n\x1b[31m\x1b[49mHTTP Error\x1b[0m \x1b[37m\x1b[49mYour request was:\x1b[0m\n\n\x1b[36m\x1b[49mPOST /Services/VA3a507dcf4b512600bf6fb565a1bc7c8b/Verifications\x1b[0m\n\n\x1b[37m\x1b[49mTwilio returned the following information:\x1b[0m\n\n\x1b[34m\x1b[49mUnable to create record: Resource not accessible with Test Account Credentials\x1b[0m\n\n\x1b[37m\x1b[49mMore information may be available here:\x1b[0m\n\n\x1b[34m\x1b[49mhttps://www.twilio.com/docs/errors/20008\x1b[0m\n\n']} None
2021-12-31 12:58:34,370 DEBUG rest_utils.py:build_response:78  Response: 200 OK 400 
[31m[49mHTTP Error[0m [37m[49mYour request was:[0m

[36m[49mPOST /Services/VA3a507dcf4b512600bf6fb565a1bc7c8b/Verifications[0m

[37m[49mTwilio returned the following information:[0m

[34m[49mUnable to create record: Resource not accessible with Test Account Credentials[0m

[37m[49mMore information may be available here:[0m

[34m[49mhttps://www.twilio.com/docs/errors/20008[0m

 {'non_field_errors': ['\n\x1b[31m\x1b[49mHTTP Error\x1b[0m \x1b[37m\x1b[49mYour request was:\x1b[0m\n\n\x1b[36m\x1b[49mPOST /Services/VA3a507dcf4b512600bf6fb565a1bc7c8b/Verifications\x1b[0m\n\n\x1b[37m\x1b[49mTwilio returned the following information:\x1b[0m\n\n\x1b[34m\x1b[49mUnable to create record: Resource not accessible with Test Account Credentials\x1b[0m\n\n\x1b[37m\x1b[49mMore information may be available here:\x1b[0m\n\n\x1b[34m\x1b[49mhttps://www.twilio.com/docs/errors/20008\x1b[0m\n\n']} None
2021-12-31 12:59:58,359 ERROR rest_utils.py:build_response:61  Response: 500 Internal server error {'non_field_errors': ['cannot unpack non-iterable NoneType object']} None
2021-12-31 12:59:58,360 DEBUG rest_utils.py:build_response:78  Response: 200 OK 500 Internal server error {'non_field_errors': ['cannot unpack non-iterable NoneType object']} None
2021-12-31 13:01:14,705 DEBUG rest_utils.py:build_response:78  Response: 200 OK 200 User OTP successfully send None None
2021-12-31 13:01:39,675 DEBUG rest_utils.py:build_response:78  Response: 200 OK 200 User OTP successfully send None None
2021-12-31 13:02:08,649 DEBUG rest_utils.py:build_response:78  Response: 200 OK 200 User OTP successfully send None None
2021-12-31 13:02:36,154 ERROR rest_utils.py:build_response:61  Response: 400 
[31m[49mHTTP Error[0m [37m[49mYour request was:[0m

[36m[49mPOST /Services/VA3a507dcf4b512600bf6fb565a1bc7c8b/Verifications[0m

[37m[49mTwilio returned the following information:[0m

[34m[49mUnable to create record: Resource not accessible with Test Account Credentials[0m

[37m[49mMore information may be available here:[0m

[34m[49mhttps://www.twilio.com/docs/errors/20008[0m

 {'non_field_errors': ['\n\x1b[31m\x1b[49mHTTP Error\x1b[0m \x1b[37m\x1b[49mYour request was:\x1b[0m\n\n\x1b[36m\x1b[49mPOST /Services/VA3a507dcf4b512600bf6fb565a1bc7c8b/Verifications\x1b[0m\n\n\x1b[37m\x1b[49mTwilio returned the following information:\x1b[0m\n\n\x1b[34m\x1b[49mUnable to create record: Resource not accessible with Test Account Credentials\x1b[0m\n\n\x1b[37m\x1b[49mMore information may be available here:\x1b[0m\n\n\x1b[34m\x1b[49mhttps://www.twilio.com/docs/errors/20008\x1b[0m\n\n']} None
2021-12-31 13:02:36,154 DEBUG rest_utils.py:build_response:78  Response: 200 OK 400 
[31m[49mHTTP Error[0m [37m[49mYour request was:[0m

[36m[49mPOST /Services/VA3a507dcf4b512600bf6fb565a1bc7c8b/Verifications[0m

[37m[49mTwilio returned the following information:[0m

[34m[49mUnable to create record: Resource not accessible with Test Account Credentials[0m

[37m[49mMore information may be available here:[0m

[34m[49mhttps://www.twilio.com/docs/errors/20008[0m

 {'non_field_errors': ['\n\x1b[31m\x1b[49mHTTP Error\x1b[0m \x1b[37m\x1b[49mYour request was:\x1b[0m\n\n\x1b[36m\x1b[49mPOST /Services/VA3a507dcf4b512600bf6fb565a1bc7c8b/Verifications\x1b[0m\n\n\x1b[37m\x1b[49mTwilio returned the following information:\x1b[0m\n\n\x1b[34m\x1b[49mUnable to create record: Resource not accessible with Test Account Credentials\x1b[0m\n\n\x1b[37m\x1b[49mMore information may be available here:\x1b[0m\n\n\x1b[34m\x1b[49mhttps://www.twilio.com/docs/errors/20008\x1b[0m\n\n']} None
2021-12-31 13:03:28,570 DEBUG rest_utils.py:build_response:78  Response: 200 OK 200 User OTP successfully send None None
2021-12-31 13:04:12,054 ERROR rest_utils.py:build_response:61  Response: 500 Internal server error {'non_field_errors': ["name 'user' is not defined"]} None
2021-12-31 13:04:12,054 DEBUG rest_utils.py:build_response:78  Response: 200 OK 500 Internal server error {'non_field_errors': ["name 'user' is not defined"]} None
2021-12-31 13:05:15,578 DEBUG rest_utils.py:build_response:78  Response: 200 OK 200 User Successfully Login None None
2021-12-31 13:05:30,993 DEBUG rest_utils.py:build_response:78  Response: 200 OK 200 User Successfully Login None None
2021-12-31 13:06:02,367 DEBUG rest_utils.py:build_response:78  Response: 200 OK 200 User Successfully Login None None
2021-12-31 13:06:04,000 DEBUG rest_utils.py:build_response:78  Response: 200 OK 200 User Successfully Login None None
2021-12-31 13:06:09,716 DEBUG rest_utils.py:build_response:78  Response: 200 OK 200 User Successfully Login None None
2021-12-31 13:06:31,332 DEBUG rest_utils.py:build_response:78  Response: 200 OK 200 User OTP successfully send None None
2021-12-31 13:08:12,957 DEBUG rest_utils.py:build_response:78  Response: 200 OK 200 User Successfully Login None None
2021-12-31 13:13:30,203 DEBUG rest_utils.py:build_response:78  Response: 200 OK 200 User Successfully Login None None
2021-12-31 13:13:33,987 DEBUG rest_utils.py:build_response:78  Response: 200 OK 200 User Successfully Login None None
2021-12-31 13:13:38,011 DEBUG rest_utils.py:build_response:78  Response: 200 OK 200 User Successfully Login None None
2021-12-31 13:13:47,891 DEBUG rest_utils.py:build_response:78  Response: 200 OK 200 User Successfully Login None None
2021-12-31 13:14:01,879 DEBUG rest_utils.py:build_response:78  Response: 200 OK 200 User OTP successfully send None None
2021-12-31 13:14:35,382 DEBUG rest_utils.py:build_response:78  Response: 200 OK 200 User OTP successfully send None None
2021-12-31 13:19:12,233 DEBUG rest_utils.py:build_response:78  Response: 200 OK 200 User Successfully Login None None
2021-12-31 13:19:21,205 DEBUG rest_utils.py:build_response:78  Response: 200 OK 200 User Successfully Login None None
2021-12-31 13:19:28,823 DEBUG rest_utils.py:build_response:78  Response: 200 OK 200 User Successfully Login None None
2021-12-31 13:20:02,366 DEBUG rest_utils.py:build_response:78  Response: 200 OK 200 User Successfully Login None None
2021-12-31 13:20:02,918 DEBUG rest_utils.py:build_response:78  Response: 200 OK 200 User Successfully Login None None
2021-12-31 13:20:49,770 DEBUG rest_utils.py:build_response:78  Response: 200 OK 200 User Successfully Login None None
2021-12-31 13:21:23,788 DEBUG rest_utils.py:build_response:78  Response: 200 OK 200 User OTP successfully send None None
2021-12-31 13:22:04,225 ERROR rest_utils.py:build_response:61  Response: 500 Internal server error {'non_field_errors': ["name 'user' is not defined"]} None
2021-12-31 13:22:04,228 DEBUG rest_utils.py:build_response:78  Response: 200 OK 500 Internal server error {'non_field_errors': ["name 'user' is not defined"]} None
2021-12-31 13:22:08,130 DEBUG rest_utils.py:build_response:78  Response: 200 OK 200 User Successfully Login None None
2021-12-31 13:22:17,997 DEBUG rest_utils.py:build_response:78  Response: 200 OK 200 User Successfully Login None None
2021-12-31 13:23:20,230 ERROR rest_utils.py:build_response:61  Response: 500 Internal server error {'non_field_errors': ['\n\x1b[31m\x1b[49mHTTP Error\x1b[0m \x1b[37m\x1b[49mYour request was:\x1b[0m\n\n\x1b[36m\x1b[49mPOST /Services/VA3a507dcf4b512600bf6fb565a1bc7c8b/VerificationCheck\x1b[0m\n\n\x1b[37m\x1b[49mTwilio returned the following information:\x1b[0m\n\n\x1b[34m\x1b[49mUnable to create record: The requested resource /Services/VA3a507dcf4b512600bf6fb565a1bc7c8b/VerificationCheck was not found\x1b[0m\n\n\x1b[37m\x1b[49mMore information may be available here:\x1b[0m\n\n\x1b[34m\x1b[49mhttps://www.twilio.com/docs/errors/20404\x1b[0m\n\n']} None
2021-12-31 13:23:20,231 DEBUG rest_utils.py:build_response:78  Response: 200 OK 500 Internal server error {'non_field_errors': ['\n\x1b[31m\x1b[49mHTTP Error\x1b[0m \x1b[37m\x1b[49mYour request was:\x1b[0m\n\n\x1b[36m\x1b[49mPOST /Services/VA3a507dcf4b512600bf6fb565a1bc7c8b/VerificationCheck\x1b[0m\n\n\x1b[37m\x1b[49mTwilio returned the following information:\x1b[0m\n\n\x1b[34m\x1b[49mUnable to create record: The requested resource /Services/VA3a507dcf4b512600bf6fb565a1bc7c8b/VerificationCheck was not found\x1b[0m\n\n\x1b[37m\x1b[49mMore information may be available here:\x1b[0m\n\n\x1b[34m\x1b[49mhttps://www.twilio.com/docs/errors/20404\x1b[0m\n\n']} None
2021-12-31 13:23:24,097 ERROR rest_utils.py:build_response:61  Response: 500 Internal server error {'non_field_errors': ['\n\x1b[31m\x1b[49mHTTP Error\x1b[0m \x1b[37m\x1b[49mYour request was:\x1b[0m\n\n\x1b[36m\x1b[49mPOST /Services/VA3a507dcf4b512600bf6fb565a1bc7c8b/VerificationCheck\x1b[0m\n\n\x1b[37m\x1b[49mTwilio returned the following information:\x1b[0m\n\n\x1b[34m\x1b[49mUnable to create record: The requested resource /Services/VA3a507dcf4b512600bf6fb565a1bc7c8b/VerificationCheck was not found\x1b[0m\n\n\x1b[37m\x1b[49mMore information may be available here:\x1b[0m\n\n\x1b[34m\x1b[49mhttps://www.twilio.com/docs/errors/20404\x1b[0m\n\n']} None
2021-12-31 13:23:24,098 DEBUG rest_utils.py:build_response:78  Response: 200 OK 500 Internal server error {'non_field_errors': ['\n\x1b[31m\x1b[49mHTTP Error\x1b[0m \x1b[37m\x1b[49mYour request was:\x1b[0m\n\n\x1b[36m\x1b[49mPOST /Services/VA3a507dcf4b512600bf6fb565a1bc7c8b/VerificationCheck\x1b[0m\n\n\x1b[37m\x1b[49mTwilio returned the following information:\x1b[0m\n\n\x1b[34m\x1b[49mUnable to create record: The requested resource /Services/VA3a507dcf4b512600bf6fb565a1bc7c8b/VerificationCheck was not found\x1b[0m\n\n\x1b[37m\x1b[49mMore information may be available here:\x1b[0m\n\n\x1b[34m\x1b[49mhttps://www.twilio.com/docs/errors/20404\x1b[0m\n\n']} None
2021-12-31 13:23:25,806 ERROR rest_utils.py:build_response:61  Response: 500 Internal server error {'non_field_errors': ['\n\x1b[31m\x1b[49mHTTP Error\x1b[0m \x1b[37m\x1b[49mYour request was:\x1b[0m\n\n\x1b[36m\x1b[49mPOST /Services/VA3a507dcf4b512600bf6fb565a1bc7c8b/VerificationCheck\x1b[0m\n\n\x1b[37m\x1b[49mTwilio returned the following information:\x1b[0m\n\n\x1b[34m\x1b[49mUnable to create record: The requested resource /Services/VA3a507dcf4b512600bf6fb565a1bc7c8b/VerificationCheck was not found\x1b[0m\n\n\x1b[37m\x1b[49mMore information may be available here:\x1b[0m\n\n\x1b[34m\x1b[49mhttps://www.twilio.com/docs/errors/20404\x1b[0m\n\n']} None
2021-12-31 13:23:25,807 DEBUG rest_utils.py:build_response:78  Response: 200 OK 500 Internal server error {'non_field_errors': ['\n\x1b[31m\x1b[49mHTTP Error\x1b[0m \x1b[37m\x1b[49mYour request was:\x1b[0m\n\n\x1b[36m\x1b[49mPOST /Services/VA3a507dcf4b512600bf6fb565a1bc7c8b/VerificationCheck\x1b[0m\n\n\x1b[37m\x1b[49mTwilio returned the following information:\x1b[0m\n\n\x1b[34m\x1b[49mUnable to create record: The requested resource /Services/VA3a507dcf4b512600bf6fb565a1bc7c8b/VerificationCheck was not found\x1b[0m\n\n\x1b[37m\x1b[49mMore information may be available here:\x1b[0m\n\n\x1b[34m\x1b[49mhttps://www.twilio.com/docs/errors/20404\x1b[0m\n\n']} None
2021-12-31 13:23:27,606 ERROR rest_utils.py:build_response:61  Response: 500 Internal server error {'non_field_errors': ['\n\x1b[31m\x1b[49mHTTP Error\x1b[0m \x1b[37m\x1b[49mYour request was:\x1b[0m\n\n\x1b[36m\x1b[49mPOST /Services/VA3a507dcf4b512600bf6fb565a1bc7c8b/VerificationCheck\x1b[0m\n\n\x1b[37m\x1b[49mTwilio returned the following information:\x1b[0m\n\n\x1b[34m\x1b[49mUnable to create record: The requested resource /Services/VA3a507dcf4b512600bf6fb565a1bc7c8b/VerificationCheck was not found\x1b[0m\n\n\x1b[37m\x1b[49mMore information may be available here:\x1b[0m\n\n\x1b[34m\x1b[49mhttps://www.twilio.com/docs/errors/20404\x1b[0m\n\n']} None
2021-12-31 13:23:27,607 DEBUG rest_utils.py:build_response:78  Response: 200 OK 500 Internal server error {'non_field_errors': ['\n\x1b[31m\x1b[49mHTTP Error\x1b[0m \x1b[37m\x1b[49mYour request was:\x1b[0m\n\n\x1b[36m\x1b[49mPOST /Services/VA3a507dcf4b512600bf6fb565a1bc7c8b/VerificationCheck\x1b[0m\n\n\x1b[37m\x1b[49mTwilio returned the following information:\x1b[0m\n\n\x1b[34m\x1b[49mUnable to create record: The requested resource /Services/VA3a507dcf4b512600bf6fb565a1bc7c8b/VerificationCheck was not found\x1b[0m\n\n\x1b[37m\x1b[49mMore information may be available here:\x1b[0m\n\n\x1b[34m\x1b[49mhttps://www.twilio.com/docs/errors/20404\x1b[0m\n\n']} None
2021-12-31 13:23:49,761 DEBUG rest_utils.py:build_response:78  Response: 200 OK 200 User Successfully Login None None
2021-12-31 13:24:24,494 DEBUG rest_utils.py:build_response:78  Response: 200 OK 200 User Successfully Login None None
2021-12-31 13:24:59,777 DEBUG rest_utils.py:build_response:78  Response: 200 OK 200 User Successfully Login None None
2021-12-31 13:25:16,228 DEBUG rest_utils.py:build_response:78  Response: 200 OK 200 User Successfully Login None None
2021-12-31 13:25:49,144 DEBUG rest_utils.py:build_response:78  Response: 200 OK 200 User OTP successfully send None None
2021-12-31 13:26:21,258 ERROR rest_utils.py:build_response:61  Response: 500 Internal server error {'non_field_errors': ["'NoneType' object has no attribute 'contact'"]} None
2021-12-31 13:26:21,260 DEBUG rest_utils.py:build_response:78  Response: 200 OK 500 Internal server error {'non_field_errors': ["'NoneType' object has no attribute 'contact'"]} None
2021-12-31 13:28:27,767 ERROR rest_utils.py:build_response:61  Response: 500 Internal server error {'non_field_errors': ["local variable 'result' referenced before assignment"]} None
2021-12-31 13:28:27,767 DEBUG rest_utils.py:build_response:78  Response: 200 OK 500 Internal server error {'non_field_errors': ["local variable 'result' referenced before assignment"]} None
2021-12-31 13:28:47,424 DEBUG rest_utils.py:build_response:78  Response: 200 OK 200 User Successfully Login None None
2021-12-31 13:29:40,273 ERROR rest_utils.py:build_response:61  Response: 500 Internal server error {'non_field_errors': ['.validate() should return the validated data']} None
2021-12-31 13:29:40,274 DEBUG rest_utils.py:build_response:78  Response: 200 OK 500 Internal server error {'non_field_errors': ['.validate() should return the validated data']} None
2021-12-31 13:29:53,364 DEBUG rest_utils.py:build_response:78  Response: 200 OK 200 User Successfully Login None None
2021-12-31 13:30:09,347 DEBUG rest_utils.py:build_response:78  Response: 200 OK 200 User Successfully Login None None
